tests/smoke/.smoke/processed_preview.csv
ask_price_1_static_plgs,bid_price_1_static_plgs,ask_price_2_static_plgs,bid_price_2_static_plgs,ask_price_3_static_plgs,bid_price_3_static_plgs,ask_price_4_static_plgs,bid_price_4_static_plgs,ask_price_5_static_plgs,bid_price_5_static_plgs,ask_price_6_static_plgs,bid_price_6_static_plgs,ask_price_7_static_plgs,bid_price_7_static_plgs,ask_price_8_static_plgs,bid_price_8_static_plgs,ask_price_9_static_plgs,bid_price_9_static_plgs,ask_price_10_static_plgs,bid_price_10_static_plgs,ask_size_1_static_exp,bid_size_1_static_exp,ask_size_2_static_exp,bid_size_2_static_exp,ask_size_3_static_exp,bid_size_3_static_exp,ask_size_4_static_exp,bid_size_4_static_exp,ask_size_5_static_exp,bid_size_5_static_exp,ask_size_6_static_exp,bid_size_6_static_exp,ask_size_7_static_exp,bid_size_7_static_exp,ask_size_8_static_exp,bid_size_8_static_exp,ask_size_9_static_exp,bid_size_9_static_exp,ask_size_10_static_exp,bid_size_10_static_exp,ask_price_1_kin_pos,ask_price_1_kin_vel,ask_price_1_kin_acc,ask_price_1_kin_jrk,bid_price_1_kin_pos,bid_price_1_kin_vel,bid_price_1_kin_acc,bid_price_1_kin_jrk,ask_price_2_kin_pos,ask_price_2_kin_vel,ask_price_2_kin_acc,ask_price_2_kin_jrk,bid_price_2_kin_pos,bid_price_2_kin_vel,bid_price_2_kin_acc,bid_price_2_kin_jrk,ask_price_3_kin_pos,ask_price_3_kin_vel,ask_price_3_kin_acc,ask_price_3_kin_jrk,bid_price_3_kin_pos,bid_price_3_kin_vel,bid_price_3_kin_acc,bid_price_3_kin_jrk,ask_price_4_kin_pos,ask_price_4_kin_vel,ask_price_4_kin_acc,ask_price_4_kin_jrk,bid_price_4_kin_pos,bid_price_4_kin_vel,bid_price_4_kin_acc,bid_price_4_kin_jrk,ask_price_5_kin_pos,ask_price_5_kin_vel,ask_price_5_kin_acc,ask_price_5_kin_jrk,bid_price_5_kin_pos,bid_price_5_kin_vel,bid_price_5_kin_acc,bid_price_5_kin_jrk,ask_price_6_kin_pos,ask_price_6_kin_vel,ask_price_6_kin_acc,ask_price_6_kin_jrk,bid_price_6_kin_pos,bid_price_6_kin_vel,bid_price_6_kin_acc,bid_price_6_kin_jrk,ask_price_7_kin_pos,ask_price_7_kin_vel,ask_price_7_kin_acc,ask_price_7_kin_jrk,bid_price_7_kin_pos,bid_price_7_kin_vel,bid_price_7_kin_acc,bid_price_7_kin_jrk,ask_price_8_kin_pos,ask_price_8_kin_vel,ask_price_8_kin_acc,ask_price_8_kin_jrk,bid_price_8_kin_pos,bid_price_8_kin_vel,bid_price_8_kin_acc,bid_price_8_kin_jrk,ask_price_9_kin_pos,ask_price_9_kin_vel,ask_price_9_kin_acc,ask_price_9_kin_jrk,bid_price_9_kin_pos,bid_price_9_kin_vel,bid_price_9_kin_acc,bid_price_9_kin_jrk,ask_price_10_kin_pos,ask_price_10_kin_vel,ask_price_10_kin_acc,ask_price_10_kin_jrk,bid_price_10_kin_pos,bid_price_10_kin_vel,bid_price_10_kin_acc,bid_price_10_kin_jrk,ask_size_1_kin_pos,ask_size_1_kin_vel,ask_size_1_kin_acc,ask_size_1_kin_jrk,bid_size_1_kin_pos,bid_size_1_kin_vel,bid_size_1_kin_acc,bid_size_1_kin_jrk,ask_size_2_kin_pos,ask_size_2_kin_vel,ask_size_2_kin_acc,ask_size_2_kin_jrk,bid_size_2_kin_pos,bid_size_2_kin_vel,bid_size_2_kin_acc,bid_size_2_kin_jrk,ask_size_3_kin_pos,ask_size_3_kin_vel,ask_size_3_kin_acc,ask_size_3_kin_jrk,bid_size_3_kin_pos,bid_size_3_kin_vel,bid_size_3_kin_acc,bid_size_3_kin_jrk,ask_size_4_kin_pos,ask_size_4_kin_vel,ask_size_4_kin_acc,ask_size_4_kin_jrk,bid_size_4_kin_pos,bid_size_4_kin_vel,bid_size_4_kin_acc,bid_size_4_kin_jrk,ask_size_5_kin_pos,ask_size_5_kin_vel,ask_size_5_kin_acc,ask_size_5_kin_jrk,bid_size_5_kin_pos,bid_size_5_kin_vel,bid_size_5_kin_acc,bid_size_5_kin_jrk,ask_size_6_kin_pos,ask_size_6_kin_vel,ask_size_6_kin_acc,ask_size_6_kin_jrk,bid_size_6_kin_pos,bid_size_6_kin_vel,bid_size_6_kin_acc,bid_size_6_kin_jrk,ask_size_7_kin_pos,ask_size_7_kin_vel,ask_size_7_kin_acc,ask_size_7_kin_jrk,bid_size_7_kin_pos,bid_size_7_kin_vel,bid_size_7_kin_acc,bid_size_7_kin_jrk,ask_size_8_kin_pos,ask_size_8_kin_vel,ask_size_8_kin_acc,ask_size_8_kin_jrk,bid_size_8_kin_pos,bid_size_8_kin_vel,bid_size_8_kin_acc,bid_size_8_kin_jrk,ask_size_9_kin_pos,ask_size_9_kin_vel,ask_size_9_kin_acc,ask_size_9_kin_jrk,bid_size_9_kin_pos,bid_size_9_kin_vel,bid_size_9_kin_acc,bid_size_9_kin_jrk,ask_size_10_kin_pos,ask_size_10_kin_vel,ask_size_10_kin_acc,ask_size_10_kin_jrk,bid_size_10_kin_pos,bid_size_10_kin_vel,bid_size_10_kin_acc,bid_size_10_kin_jrk,time,delta_t,trend_label,size_log1p,price_static,type_1,type_2,type_3,type_4,type_5,direction_-1,direction_1,time_day_sin,time_day_cos
0.3980112596527733,0.3980112596527733,0.3980112596527733,0.3980112596527733,0.3980112596527733,0.3980112596527733,0.3980112596527733,0.3980112596527733,0.3980112596527733,0.3980112596527733,0.3980112596527733,0.3980112596527733,0.3980112596527733,0.3980112596527733,0.3980112596527733,0.3980112596527733,0.3980112596527733,0.3980112596527733,0.3980112596527733,0.3980112596527733,0.008959621227116354,0.008959621227116354,0.008959621227116354,0.008959621227116354,0.008959621227116354,0.008959621227116354,0.09516258196404048,0.07225651367144714,0.09516258196404048,0.0024968776025399153,0.09516258196404048,0.04352439990637924,0.1392920235749422,0.0024968776025399153,0.024690087971667385,0.1392920235749422,0.048770575499285984,0.1392920235749422,0.00498752080731768,0.1392920235749422,27.5,-1.0000000000000036,-3.000000000000012,-3.0000000000000075,-30.5,-3.552713678800501e-15,-4.736951571734001e-15,-3.157967714489334e-15,28.5,0.9999999999999858,1.999999999999967,-2.3684757858670007e-14,-31.5,1.0658141036401503e-14,2.3684757858670007e-14,1.4210854715202004e-14,29.5,-1.1666666666666856,-2.000000000000045,-5.000000000000028,-32.5,2.1316282072803006e-14,4.7369515717340014e-14,3.157967714489334e-14,30.5,-19.6666666666667,-51.00000000000008,-59.00000000000004,-33.5,2.842170943040401e-14,5.684341886080802e-14,3.631662871662734e-14,34.5,68.16666666666667,206.99999999999994,139.99999999999997,-53.5,4.263256414560601e-14,7.579122514774402e-14,4.1053580288361343e-14,46.5,-139.50000000000003,-145.0000000000001,-72.00000000000007,-62.5,4.263256414560601e-14,8.526512829121202e-14,5.368545114631868e-14,125.5,-8.500000000000057,-7.000000000000095,-6.000000000000044,-66.5,1.4210854715202004e-14,3.789561257387201e-14,2.5263741715914672e-14,131.5,-7.166666666666771,-9.000000000000265,-14.000000000000178,-70.5,2.842170943040401e-14,4.7369515717340014e-14,2.210577400142534e-14,136.5,6.8333333333332575,40.999999999999794,21.999999999999858,-98.5,2.842170943040401e-14,9.473903143468003e-14,6.947528971876536e-14,146.5,-31.166666666666686,-5.000000000000095,-2.0000000000000693,-110.5,5.684341886080802e-14,1.2316074086508402e-13,7.579122514774402e-14,2.9444389791664403,-0.7862886429642146,-2.3588659288926417,-2.3588659288926395,2.9444389791664403,-8.881784197001252e-16,-1.7763568394002505e-15,-1.0855514018557087e-15,2.9444389791664403,2.7520102503747417,7.0765977866779055,4.71773185778527,2.9444389791664403,-8.881784197001252e-16,-1.7763568394002505e-15,-1.0855514018557087e-15,2.9444389791664403,-4.324587536303166,-4.717731857785273,-2.3588659288926372,2.9444389791664403,-8.881784197001252e-16,-1.7763568394002505e-15,-1.0855514018557087e-15,5.303304908059076,-0.13460178556326863,-0.40380535668980383,-0.40380535668980183,5.017279836814924,-8.881784197001252e-16,-2.960594732333751e-15,-1.973729821555834e-15,5.303304908059076,1.0628677934796151,2.9867007020939464,2.582895345404148,1.791759469228055,-4.440892098500626e-16,-1.1842378929335002e-15,-6.41462192005646e-16,5.303304908059076,-3.0392401859989207,-6.816759493570185,-4.637669504855834,4.499809670330265,-8.881784197001252e-16,-2.3684757858670005e-15,-1.578983857244667e-15,5.707110264748875,4.790940938195726,7.817679160442787,5.3590996443013035,1.791759469228055,-4.440892098500626e-16,-1.1842378929335002e-15,-6.41462192005646e-16,3.9318256327243257,-4.578545153612048,-10.235490744405428,-7.334970616245603,5.707110264748875,-2.6645352591003757e-15,-6.5133084111342514e-15,-4.342205607422835e-15,4.61512051684126,5.837703577176456,8.644209755357812,4.209759267272034,5.707110264748875,-2.6645352591003757e-15,-6.5133084111342514e-15,-4.342205607422835e-15,2.3978952727983707,-0.9358667782082168,3.731729787097142,3.5070385662834003,5.707110264748875,-2.6645352591003757e-15,-6.5133084111342514e-15,-4.342205607422835e-15,34200.025613151,3.360499977134168e-05,0.0,2.9444389791664403,59.0,1.0,0.0,0.0,0.0,0.0,1.0,0.0,0.608759951275282,-0.793354474193797
