tests/smoke/.smoke/raw_orderbook_preview.csv
ask_price_1,ask_size_1,bid_price_1,bid_size_1,ask_price_2,ask_size_2,bid_price_2,bid_size_2,ask_price_3,ask_size_3,bid_price_3,bid_size_3,ask_price_4,ask_size_4,bid_price_4,bid_size_4,ask_price_5,ask_size_5,bid_price_5,bid_size_5,ask_price_6,ask_size_6,bid_price_6,bid_size_6,ask_price_7,ask_size_7,bid_price_7,bid_size_7,ask_price_8,ask_size_8,bid_price_8,bid_size_8,ask_price_9,ask_size_9,bid_price_9,bid_size_9,ask_price_10,ask_size_10,bid_price_10,bid_size_10
5859400,200,5853300,18,5859800,200,5853000,150,5861000,200,5851000,5,5868900,300,5850100,89,5869500,50,5849700,5,5870000,100,5849300,300,5871000,10,5846500,300,5873900,100,5845300,300,5876500,1160,5843800,200,5879000,500,5842700,300
5859400,200,5853300,18,5859800,200,5853200,18,5861000,200,5853000,150,5868900,300,5851000,5,5869500,50,5850100,89,5870000,100,5849700,5,5871000,10,5849300,300,5873900,100,5846500,300,5876500,1160,5845300,300,5879000,500,5843800,200
5859400,200,5853300,18,5859800,200,5853200,18,5861000,200,5853100,18,5868900,300,5853000,150,5869500,50,5851000,5,5870000,100,5850100,89,5871000,10,5849700,5,5873900,100,5849300,300,5876500,1160,5846500,300,5879000,500,5845300,300
5859100,18,5853300,18,5859400,200,5853200,18,5859800,200,5853100,18,5861000,200,5853000,150,5868900,300,5851000,5,5869500,50,5850100,89,5870000,100,5849700,5,5871000,10,5849300,300,5873900,100,5846500,300,5876500,1160,5845300,300
5859100,18,5853300,18,5859200,18,5853200,18,5859400,200,5853100,18,5859800,200,5853000,150,5861000,200,5851000,5,5868900,300,5850100,89,5869500,50,5849700,5,5870000,100,5849300,300,5871000,10,5846500,300,5873900,100,5845300,300
5859100,18,5853300,18,5859200,18,5853200,18,5859300,18,5853100,18,5859400,200,5853000,150,5859800,200,5851000,5,5861000,200,5850100,89,5868900,300,5849700,5,5869500,50,5849300,300,5870000,100,5846500,300,5871000,10,5845300,300
5859100,18,5853300,18,5859200,18,5853200,18,5859300,18,5853100,18,5859400,200,5853000,150,5859800,200,5851000,5,5861000,200,5850100,89,5868900,300,5850000,100,5869500,50,5849700,5,5870000,100,5849300,300,5871000,10,5846500,300
5859100,18,5853300,18,5859200,18,5853200,18,5859300,118,5853100,18,5859400,200,5853000,150,5859800,200,5851000,5,5861000,200,5850100,89,5868900,300,5850000,100,5869500,50,5849700,5,5870000,100,5849300,300,5871000,10,5846500,300
